<?xml version="1.0"?>
<robot name="delta_robot" xmlns:xacro="http://www.ros.org/wiki/xacro">
  <xacro:property name="PI" value="3.1415926535897931"/>
  <xacro:property name="width" value="0.01" /> <!-- all links -->


  <xacro:property name="width_m" value="0.01" /> <!-- all links -->
  <xacro:property name="length_m" value="0.03" /> <!-- all links -->

  <xacro:property name="distance_ground" value="1" /> <!-- distance from ground if there is not a uav-->
  <xacro:property name="distance_arm_uav" value="0.12" /> <!-- distance arm from uav-->
  <xacro:property name="mass_base" value="0.48" /> <!-- base mass-->
  <xacro:property name="mass_low_base" value="0.03" /> <!-- low base mass -->
  <xacro:property name="length_base" value="0.3" /> <!-- base length -->
  <xacro:property name="mass_uleg" value="0.0466" /> <!--upper leg mass-->
  <xacro:property name="length_uleg" value="0.2" /> <!-- upper leg length -->
  <xacro:property name="width_uleg" value="0.05" /> <!-- upper leg width -->

  <xacro:property name="mass_lleg" value="0.04" /> <!-- low leg mass-->
  <xacro:property name="length_lleg" value="0.51" /> <!-- low leg length-->
  <xacro:property name="width_lleg" value="0.002" /> <!-- low leg width -->
  <xacro:property name="mass_con" value="0.0173" /> <!-- connector mass-->

  <xacro:property name="namespace" value="delta" />

  <xacro:macro name="default_inertial2" params="mass length width">
	 <inertia ixx="${1/12*mass*(width*width+length*length)}" ixy="0.0" ixz="0.0"
	  	  iyy="${1/12*mass*(width*width+length*length)}" iyz="0.0"
	 	  izz="${1/12*mass*(width*width+width*width)}"/>
  </xacro:macro>
  <xacro:macro name="default_inertial3" params="mass length width">
	 <inertia ixx="${1/12*mass*(width*width+length*length)}" ixy="0.0" ixz="0.0"
	  	  iyy="${1/12*mass*(width*width+length*length)}" iyz="0.0"
	 	  izz="${1/12*mass*(length*length+length*length)}"/>
  </xacro:macro>


   <link name="world"/>

<!-- Base superior -->
   <joint name="base" type="fixed">
 	     <parent link="world"/>
 	     <child link="link_0"/>
       <axis xyz="0 0 0"/>
       <origin xyz="0 0 ${-distance_arm_uav+distance_ground}" rpy="0 0 1.57"/>
   </joint>


   <link name="link_0">
      <inertial>
        <origin xyz="-0.0 -0.0 -0.0" rpy="0 0 0"/>
        <mass value="${mass_base}"/>
        <xacro:default_inertial3 mass="${mass_base}" length="${length_base}" width="${width_m}" />
      </inertial>
      <visual>
        <origin xyz="-0.147 -0.085 -0.01" rpy="0 0 0"/>
   	    <geometry>
          <mesh filename="package://delta_robot/meshes/fixed_base2.dae" scale="0.001 0.001 0.001" />
        </geometry>
      </visual>
      <visual>
        <origin xyz="-0.0 0 ${distance_arm_uav/2}" rpy="0 0 0"/>
        <geometry>
   	      <box size="0.05 0.05 ${distance_arm_uav}  "/>

        </geometry>
      </visual>
      <collision>
        <origin xyz="-0.147 -0.085 -0.01" rpy="0 0 0"/>
        <geometry>
            <mesh filename="package://delta_robot/meshes/fixed_base2.dae" scale="0.001 0.001 0.001" />
        </geometry>
      </collision>
    </link>



 <!-- Patas unidas a los motors -->
    <joint name="link_0_JOINT_1" type="revolute">
      <origin xyz="0 -${1.717/6*length_base} 0" rpy="0 0 0"/>
    	<parent link="link_0"/>
    	<child link="uleg_1"/>
      <limit effort="20" velocity="1.0" lower="-1.1" upper="1.1" />
      <axis xyz="1 0 0"/>
    </joint>

    <joint name="link_0_JOINT_2" type="revolute">
      <origin xyz="${-length_base/4} ${1.717/4*length_base-1.717/6*length_base+0.005} 0" rpy="0 0 ${4*PI/3}"/>
    	<parent link="link_0"/>
    	<child link="uleg_2"/>
      <limit effort="20" velocity="1.0" lower="-1.1" upper="1.1" />
      <axis xyz="1 0 0"/>
    </joint>

    <joint name="link_0_JOINT_3" type="revolute">
      <origin xyz="${length_base/4} ${1.717/4*length_base-1.717/6*length_base} 0" rpy="0 0 ${2*PI/3}"/>
    	<parent link="link_0"/>
    	<child link="uleg_3"/>
      <limit effort="20" velocity="1.0" lower="-1.1" upper="1.1" />
      <axis xyz="1 0 0"/>
    </joint>

    <link name="uleg_1">
      <inertial>
        <origin xyz="0 ${-length_uleg/2+width_uleg/2+0.004}  0 " rpy="${PI/2} 0 0"/>
        <mass value="${mass_uleg}"/>
       	<xacro:default_inertial3 mass="${mass_uleg}" width="${length_uleg}" length="${width_uleg}" />
      </inertial>
      <visual>
        <origin xyz="0 ${width_uleg/2+0.004} ${width_uleg/2+0.003} " rpy="${PI/2} ${PI} ${PI/2}"/>
      	<geometry>
          <mesh filename="package://delta_robot/meshes/upper_leg.STL" scale="0.001 0.001 0.001" />
        </geometry>
      </visual>
      <collision>
     	  <origin xyz="0 ${width_uleg/2+0.004} ${width_uleg/2} " rpy="${PI/2} ${PI} ${PI/2}"/>
    	  <geometry>
          <mesh filename="package://delta_robot/meshes/upper_leg.STL" scale="0.001 0.001 0.001" />
        </geometry>
      </collision>
     </link>

     <link name="uleg_2">
      <inertial>
           <origin xyz="0 ${-length_uleg/2+width_uleg/2+0.004}  0 " rpy="${PI/2} 0 0"/>
           <mass value="${mass_uleg}"/>
    	      <xacro:default_inertial3 mass="${mass_uleg}" width="${length_uleg}" length="${width_uleg}" />
       </inertial>
       <visual>
         <origin xyz="0 ${width_uleg/2+0.004} ${width_uleg/2+0.003} " rpy="${PI/2} ${PI} ${PI/2}"/>
    	   <geometry>
           <mesh filename="package://delta_robot/meshes/upper_leg.STL" scale="0.001 0.001 0.001" />
         </geometry>
       </visual>
       <collision>
  	      <origin xyz="0 ${width_uleg/2+0.004} ${width_uleg/2} " rpy="${PI/2} ${PI} ${PI/2}"/>
  	      <geometry>
             <mesh filename="package://delta_robot/meshes/upper_leg.STL" scale="0.001 0.001 0.001" />
         </geometry>
       </collision>
     </link>

     <link name="uleg_3">
       <inertial>
           <origin xyz="0 ${-length_uleg/2+width_uleg/2+0.004}  0 " rpy="${PI/2} 0 0"/>
           <mass value="${mass_uleg}"/>
           <xacro:default_inertial3 mass="${mass_uleg}" width="${length_uleg}" length="${width_uleg}" />
       </inertial>
       <visual>
         <origin xyz="0 ${width_uleg/2+0.004} ${width_uleg/2+0.003} " rpy="${PI/2} ${PI} ${PI/2}"/>
       	 <geometry>
           <mesh filename="package://delta_robot/meshes/upper_leg.STL" scale="0.001 0.001 0.001" />
         </geometry>
       </visual>
        <collision>
          <origin xyz="0 ${width_uleg/2+0.004} ${width_uleg/2} " rpy="${PI/2} ${PI} ${PI/2}"/>
       	  <geometry>
            <mesh filename="package://delta_robot/meshes/upper_leg.STL" scale="0.001 0.001 0.001" />
          </geometry>
        </collision>
      </link>
<!-- ****************************************************************** -->
<!-- Brazo vertical de union con "upper_leg" 1 -->
<!-- ****************************************************************** -->
<!-- barilla horizontal de uninon entre "upper_leg" y la pata larga 1-->
      <joint name="uleg1_con" type="continuous">
    	   <origin xyz="0 -0.2 0" rpy="${PI/2-1.0358} 0 0"/>
    	   <parent link="uleg_1"/>
    	   <child link="con1"/>
         <axis xyz="1 0 0"/>
      </joint>

      <link name="con1">
        <inertial>
          <origin xyz="0.005 0 0 " rpy="0 ${PI/2} 0"/>
          <mass value="${mass_con}"/>
         	<xacro:default_inertial2 mass="${mass_con}" width="0.002" length="0.05" />
        </inertial>
        <visual>
          <origin xyz="0.005 0 0 " rpy="0 ${PI/2} 0"/>
          <geometry>
            <cylinder length="0.05" radius="0.002" />
          </geometry>
        </visual>
        <collision>
       	  <origin xyz="0.005 0 0 " rpy="0 ${PI/2} 0 "/>
          <geometry>
            <cylinder length="0.05" radius="0.002" />
          </geometry>
        </collision>
       </link>
<!-- barilla vertical larga 1 -->
       <joint name="con_lleg_1" type="continuous">
         <origin xyz="-0.02 0 0" rpy="0 0 0"/>
       	 <parent link="con1"/>
       	 <child link="lleg_1"/>
         <axis xyz="0 1 0"/>
       </joint>

       <link name="lleg_1">
         <inertial>
           <origin xyz="0 0 ${-length_lleg/2} " rpy="0 0 0"/>
           <mass value="${mass_lleg}"/>
        	 <xacro:default_inertial3 mass="${mass_lleg}" width="${length_lleg}" length="${width_lleg}" />
         </inertial>
         <visual>
           <origin xyz=" 0 0 ${-length_lleg/2} " rpy="0 0 0"/>
           <geometry>
             <cylinder length="${length_lleg}" radius="${width_lleg}" />
           </geometry>
         </visual>
         <collision>
        	<origin xyz="0 0 ${-length_lleg/2} " rpy="0 0 0 "/>
             <geometry>
                 <cylinder length="${length_lleg}" radius="${width_lleg}" />
             </geometry>
           </collision>
       </link>
<!-- barilla vertical 2 -->
       <joint name="con2_lleg_1" type="continuous">
         <origin xyz="0.03 0 0" rpy="0 0 0"/>
       	 <parent link="con1"/>
       	 <child link="lleg_12"/>
       	 <mimic joint="con_lleg_1"/>
        <axis xyz="0 1 0"/>
      </joint>

       <link name="lleg_12">
         <inertial>
           <origin xyz="0 0 ${-length_lleg/2} " rpy="0 0 0"/>
           <mass value="${mass_lleg}"/>
        	 <xacro:default_inertial3 mass="${mass_lleg}" width="${length_lleg}" length="${width_lleg}" />
          </inertial>

          <visual>
             <origin xyz=" 0 0 ${-length_lleg/2} " rpy="0 0 0"/>
             <geometry>
                 <cylinder length="${length_lleg}" radius="${width_lleg}" />
             </geometry>
          </visual>
          <collision>
        	   <origin xyz="0 0 ${-length_lleg/2} " rpy="0 0 0 "/>
              <geometry>
                <cylinder length="${length_lleg}" radius="${width_lleg}" />
              </geometry>
          </collision>
        </link>
<!-- ****************************************************************** -->
<!-- Brazo vertical de union con "upper_leg" 2 -->
<!-- ****************************************************************** -->
<!-- barilla horizontal de uninon entre "upper_leg" y la pata larga 2-->
        <joint name="uleg2_con" type="continuous">
          <origin xyz="0 -0.2 0" rpy="${PI/2-1.0358} 0 0"/>
          <parent link="uleg_2"/>
          <child link="con2"/>
          <axis xyz="1 0 0"/>
        </joint>

        <link name="con2">
          <inertial>
            <origin xyz="0.005 0 0 " rpy="0 ${PI/2} 0"/>
            <mass value="${mass_con}"/>
           	<xacro:default_inertial2 mass="${mass_con}" width="0.002" length="0.05" />
          </inertial>

          <visual>
            <origin xyz="0.005 0 0 " rpy="0 ${PI/2} 0"/>
            <geometry>
                <cylinder length="0.05" radius="0.002" />
            </geometry>
          </visual>
          <collision>
         	  <origin xyz="0.005 0 0 " rpy="0 ${PI/2} 0 "/>
              <geometry>
                  <cylinder length="0.05" radius="0.002" />
              </geometry>
          </collision>
         </link>
<!-- barilla vertical larga 1 -->
         <joint name="con_lleg_2" type="continuous">
           <origin xyz="-0.02 0 0" rpy="0 0 0"/>
         	 <parent link="con2"/>
         	 <child link="lleg_2"/>
           <axis xyz="0 1 0"/>
         </joint>

         <link name="lleg_2">
           <inertial>
            <origin xyz="0 0 ${-length_lleg/2} " rpy="0 0 0"/>
            <mass value="${mass_lleg}"/>
          	<xacro:default_inertial3 mass="${mass_lleg}" width="${length_lleg}" length="${width_lleg}" />
           </inertial>

           <visual>
             <origin xyz=" 0 0 ${-length_lleg/2} " rpy="0 0 0"/>
             <geometry>
                 <cylinder length="${length_lleg}" radius="${width_lleg}" />
             </geometry>
           </visual>
           <collision>
             <origin xyz="0 0 ${-length_lleg/2} " rpy="0 0 0 "/>
             <geometry>
                 <cylinder length="${length_lleg}" radius="${width_lleg}" />
             </geometry>
           </collision>
          </link>
<!-- barilla vertical larga 2 -->
          <joint name="con2_lleg_2" type="continuous">
            <origin xyz="0.03 0 0" rpy="0 0 0"/>
            <parent link="con2"/>
            <child link="lleg_22"/>
            <axis xyz="0 1 0"/>
          </joint>

          <link name="lleg_22">
            <inertial>
                <origin xyz="0 0 ${-length_lleg/2} " rpy="0 0 0"/>
                <mass value="${mass_lleg}"/>
           	    <xacro:default_inertial3 mass="${mass_lleg}" width="${length_lleg}" length="${width_lleg}" />
            </inertial>

            <visual>
                <origin xyz=" 0 0 ${-length_lleg/2} " rpy="0 0 0"/>
                <geometry>
                    <cylinder length="${length_lleg}" radius="${width_lleg}" />
                </geometry>
            </visual>
            <collision>
           	  <origin xyz="0 0 ${-length_lleg/2} " rpy="0 0 0 "/>
                <geometry>
                    <cylinder length="${length_lleg}" radius="${width_lleg}" />
                </geometry>
            </collision>
           </link>
 <!-- ****************************************************************** -->
 <!-- Brazo vertical de union con "upper_leg" 3 -->
 <!-- ****************************************************************** -->
 <!-- barilla horizontal de uninon entre "upper_leg" y la pata larga 3-->
         <joint name="uleg3_con" type="continuous">
           <origin xyz="0 -0.2 0" rpy="${PI/2-1.0358} 0 0"/>
           <parent link="uleg_3"/>
           <child link="con3"/>
           <axis xyz="1 0 0"/>
         </joint>

         <link name="con3">
           <inertial>
             <origin xyz="0.005 0 0 " rpy="0 ${PI/2} 0"/>
             <mass value="${mass_con}"/>
        	    <xacro:default_inertial2 mass="${mass_con}" width="0.002" length="0.05" />
           </inertial>

          <visual>
             <origin xyz="0.005 0 0 " rpy="0 ${PI/2} 0"/>
             <geometry>
                 <cylinder length="0.05" radius="0.002" />
             </geometry>
          </visual>
          <collision>
          	<origin xyz="0.005 0 0 " rpy="0 ${PI/2} 0 "/>
             <geometry>
                 <cylinder length="0.05" radius="0.002" />
             </geometry>
          </collision>
        </link>

<!-- barilla vertical larga 1 -->
        <joint name="con_lleg_3" type="continuous">
          <origin xyz="-0.02 0 0" rpy="0 0 0"/>
          <parent link="con3"/>
          <child link="lleg_3"/>
          <axis xyz="0 1 0"/>
        </joint>

        <link name="lleg_3">
          <inertial>
            <origin xyz="0 0 ${-length_lleg/2} " rpy="0 0 0"/>
            <mass value="${mass_lleg}"/>
            <xacro:default_inertial3 mass="${mass_lleg}" width="${length_lleg}" length="${width_lleg}" />
          </inertial>

          <visual>
            <origin xyz=" 0 0 ${-length_lleg/2} " rpy="0 0 0"/>
            <geometry>
                <cylinder length="${length_lleg}" radius="0.002" />
            </geometry>
          </visual>
          <collision>
            <origin xyz="0 0 ${-length_lleg/2} " rpy="0 0 0 "/>
            <geometry>
                <cylinder length="${length_lleg}" radius="0.002" />
            </geometry>
          </collision>
         </link>

<!-- barilla vertical larga 1 -->
        <joint name="con2_lleg_3" type="continuous">
          <origin xyz="0.03 0 0" rpy="0 0 0"/>
          <parent link="con3"/>
          <child link="lleg_32"/>
          <axis xyz="0 1 0"/>
        </joint>

        <link name="lleg_32">
          <inertial>
              <origin xyz="0 0 ${-length_lleg/2} " rpy="0 0 0"/>
              <mass value="${mass_lleg}"/>
              <xacro:default_inertial3 mass="${mass_lleg}" width="${length_lleg}" length="${width_lleg}" />
          </inertial>

          <visual>
            <origin xyz=" 0 0 ${-length_lleg/2} " rpy="0 0 0"/>
            <geometry>
                <cylinder length="${length_lleg}" radius="${width_lleg}" />
            </geometry>
          </visual>
          <collision>
            <origin xyz="0 0 ${-length_lleg/2} " rpy="0 0 0 "/>
            <geometry>
                <cylinder length="${length_lleg}" radius="${width_lleg}" />
            </geometry>
          </collision>
         </link>

<!-- ****************************************************************** -->
<!-- Barillas horizontales de abajo de las patas -->
<!-- ****************************************************************** -->
<!-- barilla horizontal de abajo de uninon entre "upper_leg" y la pata larga 3-->
         <joint name="con33_lleg_3" type="continuous">
           <origin xyz="0 0 -0.51" rpy="0 0 0"/>
         	 <parent link="lleg_32"/>
         	 <child link="con33"/>
           <axis xyz="0 1 0"/>
         </joint>

         <link name="con33">
           <inertial>
             <origin xyz="-0.025  0 0 " rpy="0 ${PI/2} 0"/>
             <mass value="${mass_con}"/>
        	   <xacro:default_inertial2 mass="${mass_con}" width="0.002" length="0.05" />
          </inertial>

           <visual>
             <origin xyz="-0.025 0 0  " rpy="0 ${PI/2} 0"/>
             <geometry>
                 <cylinder length="0.05" radius="0.002" />
             </geometry>
           </visual>
           <collision>
        	    <origin xyz="-0.025 0  0 " rpy="0 ${PI/2} 0 "/>
              <geometry>
                 <cylinder length="0.05" radius="0.002" />
               </geometry>
           </collision>
          </link>

<!-- barilla horizontal de abajo de uninon entre "upper_leg" y la pata larga 2-->
          <joint name="con23_lleg_2" type="continuous">
            <origin xyz="0 0 -0.51" rpy="0 0 0"/>
            <parent link="lleg_22"/>
            <child link="con23"/>
            <axis xyz="0 1 0"/>
          </joint>

          <link name="con23">
            <inertial>
              <origin xyz="-0.025  0 0 " rpy="0 ${PI/2} 0"/>
              <mass value="${mass_con}"/>
           	  <xacro:default_inertial2 mass="${mass_con}" width="0.002" length="0.05" />
            </inertial>

            <visual>
              <origin xyz="-0.025 0 0  " rpy="0 ${PI/2} 0"/>
              <geometry>
                  <cylinder length="0.05" radius="0.002" />
              </geometry>
            </visual>
            <collision>
         	    <origin xyz="-0.025 0  0 " rpy="0 ${PI/2} 0 "/>
              <geometry>
                  <cylinder length="0.05" radius="0.002" />
              </geometry>
            </collision>
         </link>

<!-- barilla horizontal de abajo de uninon entre "upper_leg" y la pata larga 1-->
         <joint name="con13_lleg_1" type="continuous">
           <origin xyz="0 0 -0.51" rpy="0 0 0"/>
           <parent link="lleg_12"/>
           <child link="con13"/>
           <axis xyz="0 1 0"/>
         </joint>

         <link name="con13">
           <inertial>
             <origin xyz="-0.025  0 0 " rpy="0 ${PI/2} 0"/>
             <mass value="${mass_con}"/>
        	   <xacro:default_inertial2 mass="${mass_con}" width="0.002" length="0.05" />
           </inertial>

           <visual>
             <origin xyz="-0.025 0 0  " rpy="0 ${PI/2} 0"/>
             <geometry>
                 <cylinder length="0.05" radius="0.002" />
             </geometry>
           </visual>
           <collision>
        	    <origin xyz="-0.025 0  0 " rpy="0 ${PI/2} 0 "/>
              <geometry>
                 <cylinder length="0.05" radius="0.002" />
               </geometry>
           </collision>
        </link>


<!-- ****************************************************************** -->
<!-- Union inferior de las patas con el end effector -->
<!-- ****************************************************************** -->
<!-- Union de la pata larga 1-->
        <joint name='lleg1_base' type='continuous'>
          <origin xyz=" 0 0 0" rpy="-0.5 0 0"/>
          <parent link="con13"/>
          <child link="low_base"/>
          <axis xyz="1 0 0"/>
        </joint>

        <link name='low_base'>
          <inertial>
            <origin xyz="${-length_m} ${length_m} 0" rpy="0 -0 0"/>
            <mass value="${mass_low_base}"/>
           	<xacro:default_inertial3 mass="${mass_low_base}" width="${length_m}" length="${length_m}" />
          </inertial>
          <visual name='low_base_visual'>
            <origin xyz="-0.07 -0.015 -0.012" rpy="0 -0 0"/>
    	      <geometry>
              <mesh filename="package://delta_robot/meshes/Platform.STL" scale="0.001 0.001 0.001" />
            </geometry>
          </visual>
        </link>

</robot>
